{"name": "test_list3", "status": "failed", "statusDetails": {"message": "AssertionError: assert 2 in [0, 1, [1, 2]]", "trace": "self = <tests.test_assertions.TestCollections object at 0x10d85d410>\n\n    def test_list3(self):\n>       assert 2 in [0,1,[1,2]]\nE       assert 2 in [0, 1, [1, 2]]\n\ntests/test_assertions.py:53: AssertionError"}, "start": 1591177964100, "stop": 1591177964100, "uuid": "f2b685e7-53b4-4cfd-9de0-e3f94105af7f", "historyId": "f41f6d01134d681b0f77d0ee8debd4ef", "testCaseId": "23ffd3bd274984d6f5445e18db01bc4f", "fullName": "tests.test_assertions.TestCollections#test_list3", "labels": [{"name": "parentSuite", "value": "tests"}, {"name": "suite", "value": "test_assertions"}, {"name": "subSuite", "value": "TestCollections"}, {"name": "host", "value": "LIUMENGJIAdeMacBook-Pro.local"}, {"name": "thread", "value": "78362-MainThread"}, {"name": "framework", "value": "pytest"}, {"name": "language", "value": "cpython3"}, {"name": "package", "value": "tests.test_assertions"}]}